#VRML_SIM R2020a utf8
DEF ___ WorldInfo {
  basicTimeStep 27
  defaultDamping Damping {
  }
  contactProperties [
    ContactProperties {
      material1 "F"
      material2 "R"
      coulombFriction [
        0
      ]
    }
  ]
}
Viewpoint {
  orientation 0.562298339287513 0.6041288866881339 0.5646670398592968 4.224775076609613
  position 1.3012175702071342 4.817112251118857 -0.8915848747275698
}
RectangleArena {
  name "Floor"
  contactMaterial "F"
  floorSize 5 5
}
Robot {
  translation 2.34034 0.0520586 0.398843
  rotation 0 1 0 -1.5078
  children [
    Accelerometer {
      rotation 0 1 0 -1.5708
      name "ac"
      lookupTable [
        -1 -9.80665 0
        0 0 0
        1 9.80665 0
      ]
      yAxis FALSE
      zAxis FALSE
    }
    DEF Main Receiver {
      name "rx"
      channel 2
    }
    DEF Main Emitter {
      name "tx"
      channel 2
    }
    DistanceSensor {
      translation 0 -0.02 0.075
      rotation 0 1 0 -1.5708
      children [
        Shape {
          appearance PBRAppearance {
            baseColor 1 0.5 0
            roughness 1
            metalness 0
          }
          geometry Box {
            size 0.01 0.01 0.02
          }
        }
      ]
      name "ds"
      lookupTable [
        0 0 0
        0.1 0.1 0
        0.2 0.2 0
        0.3 0.3 0
        0.375 0.375 0
      ]
      type "laser"
      aperture 0.025
      gaussianWidth 0.5
    }
    Receiver {
      translation 0 0 0.075
      children [
        Shape {
          appearance PBRAppearance {
            baseColor 0 1 1
            roughness 1
            metalness 0
          }
          geometry Sphere {
            radius 0.005
          }
        }
      ]
      name "receiver(0)"
      type "infra-red"
      aperture 0.7461548752580024
    }
    Receiver {
      translation 0.0375 0 0.0649519
      rotation 0 1 0 0.523599
      children [
        Shape {
          appearance PBRAppearance {
            baseColor 0 1 1
            roughness 1
            metalness 0
          }
          geometry Sphere {
            radius 0.005
          }
        }
      ]
      name "receiver(1)"
      type "infra-red"
      aperture 0.7461548752580024
    }
    Receiver {
      translation 0.0649519 0 0.0375
      rotation 0 1 0 1.0472
      children [
        Shape {
          appearance PBRAppearance {
            baseColor 0 1 1
            roughness 1
            metalness 0
          }
          geometry Sphere {
            radius 0.005
          }
        }
      ]
      name "receiver(2)"
      type "infra-red"
      aperture 0.7461548752580024
    }
    Receiver {
      translation 0.075 0 0
      rotation 0 1 0 1.5708
      children [
        Shape {
          appearance PBRAppearance {
            baseColor 0 1 1
            roughness 1
            metalness 0
          }
          geometry Sphere {
            radius 0.005
          }
        }
      ]
      name "receiver(3)"
      type "infra-red"
      aperture 0.7461548752580024
    }
    Receiver {
      translation 0.0649519 0 -0.0375
      rotation 0 1 0 2.0944
      children [
        Shape {
          appearance PBRAppearance {
            baseColor 0 1 1
            roughness 1
            metalness 0
          }
          geometry Sphere {
            radius 0.005
          }
        }
      ]
      name "receiver(4)"
      type "infra-red"
      aperture 0.7461548752580024
    }
    Receiver {
      translation 0.0375 0 -0.0649519
      rotation 0 1 0 2.61799
      children [
        Shape {
          appearance PBRAppearance {
            baseColor 0 1 1
            roughness 1
            metalness 0
          }
          geometry Sphere {
            radius 0.005
          }
        }
      ]
      name "receiver(5)"
      type "infra-red"
      aperture 0.7461548752580024
    }
    Receiver {
      translation 0 0 -0.075
      rotation 0 1 0 3.14159
      children [
        Shape {
          appearance PBRAppearance {
            baseColor 0 1 1
            roughness 1
            metalness 0
          }
          geometry Sphere {
            radius 0.005
          }
        }
      ]
      name "receiver(6)"
      type "infra-red"
      aperture 0.7461548752580024
    }
    Receiver {
      translation -0.0375 0 -0.0649519
      rotation 0 1 0 -2.61799
      children [
        Shape {
          appearance PBRAppearance {
            baseColor 0 1 1
            roughness 1
            metalness 0
          }
          geometry Sphere {
            radius 0.005
          }
        }
      ]
      name "receiver(7)"
      type "infra-red"
      aperture 0.7461548752580024
    }
    Receiver {
      translation -0.0649519 0 -0.0375
      rotation 0 1 0 -2.0944
      children [
        Shape {
          appearance PBRAppearance {
            baseColor 0 1 1
            roughness 1
            metalness 0
          }
          geometry Sphere {
            radius 0.005
          }
        }
      ]
      name "receiver(8)"
      type "infra-red"
      aperture 0.7461548752580024
    }
    Receiver {
      translation -0.075 0 0
      rotation 0 1 0 -1.5708
      children [
        Shape {
          appearance PBRAppearance {
            baseColor 0 1 1
            roughness 1
            metalness 0
          }
          geometry Sphere {
            radius 0.005
          }
        }
      ]
      name "receiver(9)"
      type "infra-red"
      aperture 0.7461548752580024
    }
    Receiver {
      translation -0.0649519 0 0.0375
      rotation 0 1 0 -1.0472
      children [
        Shape {
          appearance PBRAppearance {
            baseColor 0 1 1
            roughness 1
            metalness 0
          }
          geometry Sphere {
            radius 0.005
          }
        }
      ]
      name "receiver(10)"
      type "infra-red"
      aperture 0.7461548752580024
    }
    Receiver {
      translation -0.0375 0 0.0649519
      rotation 0 1 0 -0.523599
      children [
        Shape {
          appearance PBRAppearance {
            baseColor 0 1 1
            roughness 1
            metalness 0
          }
          geometry Sphere {
            radius 0.005
          }
        }
      ]
      name "receiver(11)"
      type "infra-red"
      aperture 0.7461548752580024
    }
    Emitter {
      translation 0 0.0055 0.075
      children [
        Shape {
          appearance PBRAppearance {
            baseColor 1 1 0
            roughness 1
            metalness 0
          }
          geometry Sphere {
            radius 0.005
          }
        }
      ]
      name "emitter(0)"
      type "infra-red"
      range 0.3
      maxRange 0.3
      aperture 0.170196222099557
    }
    Emitter {
      translation 0.0375 0.0055 0.0649519
      rotation 0 1 0 0.523599
      children [
        Shape {
          appearance PBRAppearance {
            baseColor 1 1 0
            roughness 1
            metalness 0
          }
          geometry Sphere {
            radius 0.005
          }
        }
      ]
      name "emitter(1)"
      type "infra-red"
      range 0.3
      maxRange 0.3
      aperture 0.170196222099557
    }
    Emitter {
      translation 0.0649519 0.0055 0.0375
      rotation 0 1 0 1.0472
      children [
        Shape {
          appearance PBRAppearance {
            baseColor 1 1 0
            roughness 1
            metalness 0
          }
          geometry Sphere {
            radius 0.005
          }
        }
      ]
      name "emitter(2)"
      type "infra-red"
      range 0.3
      maxRange 0.3
      aperture 0.170196222099557
    }
    Emitter {
      translation 0.075 0.0055 0
      rotation 0 1 0 1.5708
      children [
        Shape {
          appearance PBRAppearance {
            baseColor 1 1 0
            roughness 1
            metalness 0
          }
          geometry Sphere {
            radius 0.005
          }
        }
      ]
      name "emitter(3)"
      type "infra-red"
      range 0.3
      maxRange 0.3
      aperture 0.170196222099557
    }
    Emitter {
      translation 0.0649519 0.0055 -0.0375
      rotation 0 1 0 2.0944
      children [
        Shape {
          appearance PBRAppearance {
            baseColor 1 1 0
            roughness 1
            metalness 0
          }
          geometry Sphere {
            radius 0.005
          }
        }
      ]
      name "emitter(4)"
      type "infra-red"
      range 0.3
      maxRange 0.3
      aperture 0.170196222099557
    }
    Emitter {
      translation 0.0375 0.0055 -0.0649519
      rotation 0 1 0 2.61799
      children [
        Shape {
          appearance PBRAppearance {
            baseColor 1 1 0
            roughness 1
            metalness 0
          }
          geometry Sphere {
            radius 0.005
          }
        }
      ]
      name "emitter(5)"
      type "infra-red"
      range 0.3
      maxRange 0.3
      aperture 0.170196222099557
    }
    Emitter {
      translation 0 0.0055 -0.075
      rotation 0 1 0 3.14159
      children [
        Shape {
          appearance PBRAppearance {
            baseColor 1 1 0
            roughness 1
            metalness 0
          }
          geometry Sphere {
            radius 0.005
          }
        }
      ]
      name "emitter(6)"
      type "infra-red"
      range 0.3
      maxRange 0.3
      aperture 0.170196222099557
    }
    Emitter {
      translation -0.0375 0.0055 -0.0649519
      rotation 0 1 0 -2.61799
      children [
        Shape {
          appearance PBRAppearance {
            baseColor 1 1 0
            roughness 1
            metalness 0
          }
          geometry Sphere {
            radius 0.005
          }
        }
      ]
      name "emitter(7)"
      type "infra-red"
      range 0.3
      maxRange 0.3
      aperture 0.170196222099557
    }
    Emitter {
      translation -0.0649519 0.0055 -0.0375
      rotation 0 1 0 -2.0944
      children [
        Shape {
          appearance PBRAppearance {
            baseColor 1 1 0
            roughness 1
            metalness 0
          }
          geometry Sphere {
            radius 0.005
          }
        }
      ]
      name "emitter(8)"
      type "infra-red"
      range 0.3
      maxRange 0.3
      aperture 0.170196222099557
    }
    Emitter {
      translation -0.075 0.0055 0
      rotation 0 1 0 -1.5708
      children [
        Shape {
          appearance PBRAppearance {
            baseColor 1 1 0
            roughness 1
            metalness 0
          }
          geometry Sphere {
            radius 0.005
          }
        }
      ]
      name "emitter(9)"
      type "infra-red"
      range 0.3
      maxRange 0.3
      aperture 0.170196222099557
    }
    Emitter {
      translation -0.0649519 0.0055 0.0375
      rotation 0 1 0 -1.0472
      children [
        Shape {
          appearance PBRAppearance {
            baseColor 1 1 0
            roughness 1
            metalness 0
          }
          geometry Sphere {
            radius 0.005
          }
        }
      ]
      name "emitter(10)"
      type "infra-red"
      range 0.3
      maxRange 0.3
      aperture 0.170196222099557
    }
    Emitter {
      translation -0.0375 0.0055 0.0649519
      rotation 0 1 0 -0.523599
      children [
        Shape {
          appearance PBRAppearance {
            baseColor 1 1 0
            roughness 1
            metalness 0
          }
          geometry Sphere {
            radius 0.005
          }
        }
      ]
      name "emitter(11)"
      type "infra-red"
      range 0.3
      maxRange 0.3
      aperture 0.170196222099557
    }
    Compass {
      rotation 0 1 0 -1.5708
      name "cp"
      lookupTable [
        -1 -1 0
        -0.707106 -0.707106 0
        0 0 0
        0.707106 0.707106 0
        1 1 0
      ]
      yAxis FALSE
    }
    HingeJoint {
      jointParameters HingeJointParameters {
        position 154.13484691268647
        anchor 0.045 0 0
      }
      device [
        PositionSensor {
          name "ps1"
        }
        RotationalMotor {
          name "wheel1"
          acceleration 0.4986655005698084
        }
      ]
    }
    HingeJoint {
      jointParameters HingeJointParameters {
        position -32.68665183029093
        anchor -0.045 0 0
      }
      device [
        PositionSensor {
          name "ps2"
        }
        RotationalMotor {
          name "wheel2"
          acceleration 0.4986655005698084
        }
      ]
    }
    DEF BODY Group {
      children [
        Transform {
          translation 0 0.04 0.045
          rotation 1 0 0 1.5708
          children [
            Shape {
              appearance PBRAppearance {
                baseColor 1 0 0
                roughness 1
                metalness 0
              }
              geometry Capsule {
                height 0.02
                radius 0.005
              }
            }
          ]
        }
        Transform {
          translation 0 -0.04 0.045
          children [
            Shape {
              appearance PBRAppearance {
                baseColor 0 1 0
                roughness 1
                metalness 0
              }
              geometry Sphere {
                radius 0.0125
              }
            }
          ]
        }
        Transform {
          translation 0 -0.04 -0.045
          children [
            Shape {
              appearance PBRAppearance {
                baseColor 0 1 0
                roughness 1
                metalness 0
              }
              geometry Sphere {
                radius 0.0125
              }
            }
          ]
        }
        Shape {
          appearance PBRAppearance {
            roughness 1
            metalness 0
          }
          geometry Cylinder {
            height 0.08
            radius 0.075
          }
        }
      ]
    }
  ]
  name "robot(4)"
  contactMaterial "R"
  boundingObject USE BODY
  physics Physics {
    density -1
    mass 1
  }
  controller ""
}
Solid {
  translation 2.091595318844917 0.04983448622345156 -1.8597252482449795
  rotation 4.052238205503477e-14 0.9999999999999999 -5.1039107454714186e-14 -0.0007821584781458088
  children [
    Shape {
      appearance PBRAppearance {
        baseColor 1 0 0
        metalness 0
      }
      geometry Box {
        size 0.1 0.1 0.1
      }
    }
  ]
  boundingObject Box {
    size 0.1 0.1 0.1
  }
  physics Physics {
    density -1
    mass 0.5
  }
  linearVelocity 1.2850913660534744e-17 -2.7625311744587616e-07 4.759903582878052e-17
  angularVelocity 9.072530889806049e-16 -1.9036065330941313e-19 -6.847165353702464e-16
}
Solid {
  translation -1.0384037237321313 0.04983448622345157 -1.8621734040319566
  rotation 5.3426907112609586e-14 1 3.912203184415506e-14 -0.0007821584781457969
  children [
    Shape {
      appearance PBRAppearance {
        baseColor 1 0 0
        metalness 0
      }
      geometry Box {
        size 0.1 0.1 0.1
      }
    }
  ]
  name "solid(3)"
  boundingObject Box {
    size 0.1 0.1 0.1
  }
  physics Physics {
    density -1
    mass 0.5
  }
  linearVelocity -4.600672636395898e-17 -2.762531174459955e-07 -1.3715719266480765e-17
  angularVelocity -1.1138890069568419e-15 1.8060991539657616e-16 1.3543546445319544e-15
}
Solid {
  translation -2.1403196753336786 0.04983448622345157 0.5869654723092879
  rotation -4.1081145272350973e-14 0.9999999999999999 3.928532787522905e-14 -0.0007821584781457641
  children [
    Shape {
      appearance PBRAppearance {
        baseColor 1 0 0
        metalness 0
      }
      geometry Box {
        size 0.1 0.1 0.1
      }
    }
  ]
  name "solid(9)"
  boundingObject Box {
    size 0.1 0.1 0.1
  }
  physics Physics {
    density -1
    mass 0.5
  }
  linearVelocity 1.6030848050039374e-17 -2.7625311744544815e-07 3.7036103431725094e-17
  angularVelocity 1.3426875284286711e-15 -2.941795785168178e-17 -4.441846717930531e-16
}
Solid {
  translation 2.088529257923207 0.04983448622345157 2.0602735526821854
  rotation -8.12562494448197e-14 1 -4.245001084438009e-14 -0.0007821584781457961
  children [
    Shape {
      appearance PBRAppearance {
        baseColor 1 0 0
        metalness 0
      }
      geometry Box {
        size 0.1 0.1 0.1
      }
    }
  ]
  name "solid(10)"
  boundingObject Box {
    size 0.1 0.1 0.1
  }
  physics Physics {
    density -1
    mass 0.5
  }
  linearVelocity 1.1050746114915422e-17 -2.7625311749340366e-07 1.6073902740172516e-17
  angularVelocity 4.364216155786677e-16 -2.173468700781081e-16 -8.76975597295608e-18
}
Solid {
  translation -0.008923847103847856 0.04983448622345157 -1.196764713244049
  rotation -3.233748538650979e-17 1 -1.8304408656813604e-18 2.0936129375218546
  children [
    Shape {
      appearance PBRAppearance {
        baseColor 1 0 0
        metalness 0
      }
      geometry Box {
        size 0.1 0.1 0.3
      }
    }
  ]
  name "solid(1)"
  boundingObject Box {
    size 0.1 0.1 0.1
  }
  physics Physics {
    density -1
    mass 0.5
  }
  linearVelocity 6.644027394758042e-17 -2.762531175421614e-07 1.015015894280455e-17
  angularVelocity -1.0464863321415031e-16 -1.4706812697463827e-16 -1.0235018907161846e-15
}
Solid {
  translation 0.9590301849492783 0.04983448622345156 1.4193899094589935
  rotation -4.351005291652916e-14 1 3.418251218770809e-14 -0.0007821584781457714
  children [
    Shape {
      appearance PBRAppearance {
        baseColor 1 0 0
        metalness 0
      }
      geometry Box {
        size 0.1 0.1 0.3
      }
    }
  ]
  name "solid(6)"
  boundingObject Box {
    size 0.1 0.1 0.1
  }
  physics Physics {
    density -1
    mass 0.5
  }
  linearVelocity 1.3599917694855794e-17 -2.7625311739717765e-07 -3.234584964126431e-17
  angularVelocity -9.059364006960474e-16 -3.6085024525928505e-17 -2.202526098667616e-16
}
Solid {
  translation -0.6302340997976068 0.04983448622345157 0.4781465651383171
  rotation 1.3257823414128894e-14 1 -1.9222523348438743e-13 -0.0007821584781458012
  children [
    Shape {
      appearance PBRAppearance {
        baseColor 1 0 0
        metalness 0
      }
      geometry Box {
        size 0.1 0.1 0.3
      }
    }
  ]
  name "solid(4)"
  boundingObject Box {
    size 0.1 0.1 0.1
  }
  physics Physics {
    density -1
    mass 0.5
  }
  linearVelocity 1.8003137037694435e-17 -2.762531174927786e-07 -1.807501001200955e-17
  angularVelocity -4.46402553503709e-16 -1.141376585593152e-16 4.1481478125407635e-16
}
Solid {
  translation 0.7519085920914172 0.049834486223451574 -2.260773218144459
  rotation -4.649987730164293e-14 1 -6.305397913277638e-14 -0.0007821584781457704
  children [
    Shape {
      appearance PBRAppearance {
        baseColor 1 0 0
        metalness 0
      }
      geometry Box {
        size 0.1 0.1 0.3
      }
    }
  ]
  name "solid(11)"
  boundingObject Box {
    size 0.1 0.1 0.1
  }
  physics Physics {
    density -1
    mass 0.5
  }
  linearVelocity -2.0105869023099953e-17 -2.7625311744785187e-07 3.3309524204919923e-17
  angularVelocity 8.921112602543151e-16 6.946419220605975e-17 4.372876606591805e-16
}
Solid {
  translation -1.3862567128215366 0.04983448622345156 1.7852539855887057
  rotation 1.9300593720611654e-17 1 9.403306894380558e-18 -2.0951772736577317
  children [
    Shape {
      appearance PBRAppearance {
        baseColor 1 0 0
        metalness 0
      }
      geometry Box {
        size 0.1 0.1 0.3
      }
    }
  ]
  name "solid(7)"
  boundingObject Box {
    size 0.1 0.1 0.1
  }
  physics Physics {
    density -1
    mass 0.5
  }
  linearVelocity -2.7640605848046033e-18 -2.762531173997037e-07 -1.2778044961424739e-17
  angularVelocity -2.2332492935773923e-16 -1.7599689482655445e-16 -3.303532122591631e-16
}
Solid {
  translation 1.1903519622888026 0.04983448622345157 -0.2704296771621587
  rotation 2.7184031197939682e-14 1 2.076802189031172e-14 -0.0007821584781457382
  children [
    Shape {
      appearance PBRAppearance {
        baseColor 1 0 0
        metalness 0
      }
      geometry Box {
        size 0.2 0.1 0.1
      }
    }
  ]
  name "solid(2)"
  boundingObject Box {
    size 0.1 0.1 0.1
  }
  physics Physics {
    density -1
    mass 0.5
  }
  linearVelocity 4.4961746547190035e-17 -2.7625311744795595e-07 -1.1174040613805184e-17
  angularVelocity 2.30466723389375e-16 -4.238309330893394e-18 -1.1218626894957498e-15
}
Solid {
  translation -1.9089744332422025 0.04983448622345157 -1.1328541051352872
  rotation -2.5093457241977813e-14 0.9999999999999999 -4.51879296097035e-14 -0.000782158478145798
  children [
    Shape {
      appearance PBRAppearance {
        baseColor 1 0 0
        metalness 0
      }
      geometry Box {
        size 0.2 0.1 0.1
      }
    }
  ]
  name "solid(8)"
  boundingObject Box {
    size 0.1 0.1 0.1
  }
  physics Physics {
    density -1
    mass 0.5
  }
  linearVelocity 4.4452971184472065e-18 -2.762531174467295e-07 2.4861576462159282e-17
  angularVelocity 4.461946267683018e-16 9.428587808471693e-17 -2.340625187030434e-16
}
Solid {
  translation -0.05143097956098956 0.04983448622345157 2.008599749003918
  rotation 4.527268952889476e-14 1 -5.88002775339009e-14 -0.0007821584781457777
  children [
    Shape {
      appearance PBRAppearance {
        baseColor 1 0 0
        metalness 0
      }
      geometry Box {
        size 0.2 0.1 0.1
      }
    }
  ]
  name "solid(5)"
  boundingObject Box {
    size 0.1 0.1 0.1
  }
  physics Physics {
    density -1
    mass 0.5
  }
  linearVelocity 2.7240246649456805e-17 -2.762531173988284e-07 2.5764606388840655e-17
  angularVelocity 6.832600503601774e-16 6.465738840309152e-17 -1.1357070496336871e-15
}
DirectionalLight {
  direction 0.5 -1 -0.5
  intensity 2
}
Robot {
  translation 1.79485 0.0420586 -1.92965
  rotation -2.044159441104964e-06 0.9999999999256364 -1.2022839521081643e-05 2.6470352880949233
  children [
    Accelerometer {
      rotation 0 1 0 -1.5708
      name "ac"
      lookupTable [
        -1 -9.80665 0
        0 0 0
        1 9.80665 0
      ]
      yAxis FALSE
      zAxis FALSE
    }
    DEF Main Receiver {
      name "rx"
      channel 2
    }
    DEF Main Emitter {
      name "tx"
      channel 2
    }
    DistanceSensor {
      translation 0 -0.02 0.075
      rotation 0 1 0 -1.5708
      children [
        Shape {
          appearance PBRAppearance {
            baseColor 1 0.5 0
            roughness 1
            metalness 0
          }
          geometry Box {
            size 0.01 0.01 0.02
          }
        }
      ]
      name "ds"
      lookupTable [
        0 0 0
        0.1 0.1 0
        0.2 0.2 0
        0.3 0.3 0
        0.375 0.375 0
      ]
      type "laser"
      aperture 0.025
      gaussianWidth 0.5
    }
    Receiver {
      translation 0 0 0.075
      children [
        Shape {
          appearance PBRAppearance {
            baseColor 0 1 1
            roughness 1
            metalness 0
          }
          geometry Sphere {
            radius 0.005
          }
        }
      ]
      name "receiver(0)"
      type "infra-red"
      aperture 0.7461548752580024
    }
    Receiver {
      translation 0.0375 0 0.0649519
      rotation 0 1 0 0.523599
      children [
        Shape {
          appearance PBRAppearance {
            baseColor 0 1 1
            roughness 1
            metalness 0
          }
          geometry Sphere {
            radius 0.005
          }
        }
      ]
      name "receiver(1)"
      type "infra-red"
      aperture 0.7461548752580024
    }
    Receiver {
      translation 0.0649519 0 0.0375
      rotation 0 1 0 1.0472
      children [
        Shape {
          appearance PBRAppearance {
            baseColor 0 1 1
            roughness 1
            metalness 0
          }
          geometry Sphere {
            radius 0.005
          }
        }
      ]
      name "receiver(2)"
      type "infra-red"
      aperture 0.7461548752580024
    }
    Receiver {
      translation 0.075 0 0
      rotation 0 1 0 1.5708
      children [
        Shape {
          appearance PBRAppearance {
            baseColor 0 1 1
            roughness 1
            metalness 0
          }
          geometry Sphere {
            radius 0.005
          }
        }
      ]
      name "receiver(3)"
      type "infra-red"
      aperture 0.7461548752580024
    }
    Receiver {
      translation 0.0649519 0 -0.0375
      rotation 0 1 0 2.0944
      children [
        Shape {
          appearance PBRAppearance {
            baseColor 0 1 1
            roughness 1
            metalness 0
          }
          geometry Sphere {
            radius 0.005
          }
        }
      ]
      name "receiver(4)"
      type "infra-red"
      aperture 0.7461548752580024
    }
    Receiver {
      translation 0.0375 0 -0.0649519
      rotation 0 1 0 2.61799
      children [
        Shape {
          appearance PBRAppearance {
            baseColor 0 1 1
            roughness 1
            metalness 0
          }
          geometry Sphere {
            radius 0.005
          }
        }
      ]
      name "receiver(5)"
      type "infra-red"
      aperture 0.7461548752580024
    }
    Receiver {
      translation 0 0 -0.075
      rotation 0 1 0 3.14159
      children [
        Shape {
          appearance PBRAppearance {
            baseColor 0 1 1
            roughness 1
            metalness 0
          }
          geometry Sphere {
            radius 0.005
          }
        }
      ]
      name "receiver(6)"
      type "infra-red"
      aperture 0.7461548752580024
    }
    Receiver {
      translation -0.0375 0 -0.0649519
      rotation 0 1 0 -2.61799
      children [
        Shape {
          appearance PBRAppearance {
            baseColor 0 1 1
            roughness 1
            metalness 0
          }
          geometry Sphere {
            radius 0.005
          }
        }
      ]
      name "receiver(7)"
      type "infra-red"
      aperture 0.7461548752580024
    }
    Receiver {
      translation -0.0649519 0 -0.0375
      rotation 0 1 0 -2.0944
      children [
        Shape {
          appearance PBRAppearance {
            baseColor 0 1 1
            roughness 1
            metalness 0
          }
          geometry Sphere {
            radius 0.005
          }
        }
      ]
      name "receiver(8)"
      type "infra-red"
      aperture 0.7461548752580024
    }
    Receiver {
      translation -0.075 0 0
      rotation 0 1 0 -1.5708
      children [
        Shape {
          appearance PBRAppearance {
            baseColor 0 1 1
            roughness 1
            metalness 0
          }
          geometry Sphere {
            radius 0.005
          }
        }
      ]
      name "receiver(9)"
      type "infra-red"
      aperture 0.7461548752580024
    }
    Receiver {
      translation -0.0649519 0 0.0375
      rotation 0 1 0 -1.0472
      children [
        Shape {
          appearance PBRAppearance {
            baseColor 0 1 1
            roughness 1
            metalness 0
          }
          geometry Sphere {
            radius 0.005
          }
        }
      ]
      name "receiver(10)"
      type "infra-red"
      aperture 0.7461548752580024
    }
    Receiver {
      translation -0.0375 0 0.0649519
      rotation 0 1 0 -0.523599
      children [
        Shape {
          appearance PBRAppearance {
            baseColor 0 1 1
            roughness 1
            metalness 0
          }
          geometry Sphere {
            radius 0.005
          }
        }
      ]
      name "receiver(11)"
      type "infra-red"
      aperture 0.7461548752580024
    }
    Emitter {
      translation 0 0.0055 0.075
      children [
        Shape {
          appearance PBRAppearance {
            baseColor 1 1 0
            roughness 1
            metalness 0
          }
          geometry Sphere {
            radius 0.005
          }
        }
      ]
      name "emitter(0)"
      type "infra-red"
      range 0.3
      maxRange 0.3
      aperture 0.170196222099557
    }
    Emitter {
      translation 0.0375 0.0055 0.0649519
      rotation 0 1 0 0.523599
      children [
        Shape {
          appearance PBRAppearance {
            baseColor 1 1 0
            roughness 1
            metalness 0
          }
          geometry Sphere {
            radius 0.005
          }
        }
      ]
      name "emitter(1)"
      type "infra-red"
      range 0.3
      maxRange 0.3
      aperture 0.170196222099557
    }
    Emitter {
      translation 0.0649519 0.0055 0.0375
      rotation 0 1 0 1.0472
      children [
        Shape {
          appearance PBRAppearance {
            baseColor 1 1 0
            roughness 1
            metalness 0
          }
          geometry Sphere {
            radius 0.005
          }
        }
      ]
      name "emitter(2)"
      type "infra-red"
      range 0.3
      maxRange 0.3
      aperture 0.170196222099557
    }
    Emitter {
      translation 0.075 0.0055 0
      rotation 0 1 0 1.5708
      children [
        Shape {
          appearance PBRAppearance {
            baseColor 1 1 0
            roughness 1
            metalness 0
          }
          geometry Sphere {
            radius 0.005
          }
        }
      ]
      name "emitter(3)"
      type "infra-red"
      range 0.3
      maxRange 0.3
      aperture 0.170196222099557
    }
    Emitter {
      translation 0.0649519 0.0055 -0.0375
      rotation 0 1 0 2.0944
      children [
        Shape {
          appearance PBRAppearance {
            baseColor 1 1 0
            roughness 1
            metalness 0
          }
          geometry Sphere {
            radius 0.005
          }
        }
      ]
      name "emitter(4)"
      type "infra-red"
      range 0.3
      maxRange 0.3
      aperture 0.170196222099557
    }
    Emitter {
      translation 0.0375 0.0055 -0.0649519
      rotation 0 1 0 2.61799
      children [
        Shape {
          appearance PBRAppearance {
            baseColor 1 1 0
            roughness 1
            metalness 0
          }
          geometry Sphere {
            radius 0.005
          }
        }
      ]
      name "emitter(5)"
      type "infra-red"
      range 0.3
      maxRange 0.3
      aperture 0.170196222099557
    }
    Emitter {
      translation 0 0.0055 -0.075
      rotation 0 1 0 3.14159
      children [
        Shape {
          appearance PBRAppearance {
            baseColor 1 1 0
            roughness 1
            metalness 0
          }
          geometry Sphere {
            radius 0.005
          }
        }
      ]
      name "emitter(6)"
      type "infra-red"
      range 0.3
      maxRange 0.3
      aperture 0.170196222099557
    }
    Emitter {
      translation -0.0375 0.0055 -0.0649519
      rotation 0 1 0 -2.61799
      children [
        Shape {
          appearance PBRAppearance {
            baseColor 1 1 0
            roughness 1
            metalness 0
          }
          geometry Sphere {
            radius 0.005
          }
        }
      ]
      name "emitter(7)"
      type "infra-red"
      range 0.3
      maxRange 0.3
      aperture 0.170196222099557
    }
    Emitter {
      translation -0.0649519 0.0055 -0.0375
      rotation 0 1 0 -2.0944
      children [
        Shape {
          appearance PBRAppearance {
            baseColor 1 1 0
            roughness 1
            metalness 0
          }
          geometry Sphere {
            radius 0.005
          }
        }
      ]
      name "emitter(8)"
      type "infra-red"
      range 0.3
      maxRange 0.3
      aperture 0.170196222099557
    }
    Emitter {
      translation -0.075 0.0055 0
      rotation 0 1 0 -1.5708
      children [
        Shape {
          appearance PBRAppearance {
            baseColor 1 1 0
            roughness 1
            metalness 0
          }
          geometry Sphere {
            radius 0.005
          }
        }
      ]
      name "emitter(9)"
      type "infra-red"
      range 0.3
      maxRange 0.3
      aperture 0.170196222099557
    }
    Emitter {
      translation -0.0649519 0.0055 0.0375
      rotation 0 1 0 -1.0472
      children [
        Shape {
          appearance PBRAppearance {
            baseColor 1 1 0
            roughness 1
            metalness 0
          }
          geometry Sphere {
            radius 0.005
          }
        }
      ]
      name "emitter(10)"
      type "infra-red"
      range 0.3
      maxRange 0.3
      aperture 0.170196222099557
    }
    Emitter {
      translation -0.0375 0.0055 0.0649519
      rotation 0 1 0 -0.523599
      children [
        Shape {
          appearance PBRAppearance {
            baseColor 1 1 0
            roughness 1
            metalness 0
          }
          geometry Sphere {
            radius 0.005
          }
        }
      ]
      name "emitter(11)"
      type "infra-red"
      range 0.3
      maxRange 0.3
      aperture 0.170196222099557
    }
    Compass {
      rotation 0 1 0 -1.5708
      name "cp"
      lookupTable [
        -1 -1 0
        -0.707106 -0.707106 0
        0 0 0
        0.707106 0.707106 0
        1 1 0
      ]
      yAxis FALSE
    }
    HingeJoint {
      jointParameters HingeJointParameters {
        position 154.13484691268647
        anchor 0.045 0 0
      }
      device [
        PositionSensor {
          name "ps1"
        }
        RotationalMotor {
          name "wheel1"
          acceleration 0.4986655005698084
        }
      ]
      endPoint Solid {
        translation 0.044999906725811556 -1.6580930141785706e-06 1.692998311292778e-06
        rotation 0.9999999999999999 4.505397002046934e-12 -3.587633551971501e-12 3.3342994331569145
        children [
          DEF TRANS_WHEEL1 Transform {
            rotation 0 0 1 1.5708
            children [
              Shape {
                appearance PBRAppearance {
                  baseColor 0 1 0
                  roughness 1
                  metalness 0
                }
                geometry Cylinder {
                  height 0.0125
                  radius 0.0525
                }
              }
            ]
          }
        ]
        name "solid(1)"
        boundingObject USE TRANS_WHEEL1
        physics Physics {
          density -1
          mass 0.5
        }
      }
    }
    HingeJoint {
      jointParameters HingeJointParameters {
        position -32.68665183029093
        anchor -0.045 0 0
      }
      device [
        PositionSensor {
          name "ps2"
        }
        RotationalMotor {
          name "wheel2"
          acceleration 0.4986655005698084
        }
      ]
      endPoint Solid {
        translation -0.04499989999478693 -2.5216667929240924e-06 -4.6957256533754403e-07
        rotation -1 -2.826952257814888e-12 2.6548224843363427e-12 1.2666251871671244
        children [
          DEF TRANS_WHEEL2 Transform {
            rotation 0 0 1 1.5708
            children [
              Shape {
                appearance PBRAppearance {
                  baseColor 0 1 0
                  roughness 1
                  metalness 0
                }
                geometry Cylinder {
                  height 0.0125
                  radius 0.0525
                }
              }
            ]
          }
        ]
        name "solid(2)"
        boundingObject USE TRANS_WHEEL2
        physics Physics {
          density -1
          mass 0.5
        }
      }
    }
    DEF BODY Group {
      children [
        Transform {
          translation 0 0.04 0.045
          rotation 1 0 0 1.5708
          children [
            Shape {
              appearance PBRAppearance {
                baseColor 1 0 0
                roughness 1
                metalness 0
              }
              geometry Capsule {
                height 0.02
                radius 0.005
              }
            }
          ]
        }
        Transform {
          translation 0 -0.04 0.045
          children [
            Shape {
              appearance PBRAppearance {
                baseColor 0 1 0
                roughness 1
                metalness 0
              }
              geometry Sphere {
                radius 0.0125
              }
            }
          ]
        }
        Transform {
          translation 0 -0.04 -0.045
          children [
            Shape {
              appearance PBRAppearance {
                baseColor 0 1 0
                roughness 1
                metalness 0
              }
              geometry Sphere {
                radius 0.0125
              }
            }
          ]
        }
        Shape {
          appearance PBRAppearance {
            baseColor 1 0.5 0
            roughness 1
            metalness 0
          }
          geometry Cylinder {
            height 0.08
            radius 0.075
          }
        }
      ]
    }
  ]
  name "robot(2)"
  contactMaterial "R"
  boundingObject USE BODY
  physics Physics {
    density -1
    mass 1
  }
  controller "newTest2"
}
Robot {
  translation 1.7855067939995384 0.05205854984711649 -2.3273822124737875
  rotation -3.8068370962538454e-05 -0.9999999988335938 2.9725602023417325e-05 -0.4945556630546965
  children [
    Accelerometer {
      rotation 0 1 0 -1.5708
      name "ac"
      lookupTable [
        -1 -9.80665 0
        0 0 0
        1 9.80665 0
      ]
      yAxis FALSE
      zAxis FALSE
    }
    DEF Main Receiver {
      name "rx"
      channel 3
    }
    DEF Main Emitter {
      name "tx"
      channel 3
    }
    DistanceSensor {
      translation 0 -0.02 0.075
      rotation 0 1 0 -1.5708
      children [
        Shape {
          appearance PBRAppearance {
            baseColor 1 0.5 0
            roughness 1
            metalness 0
          }
          geometry Box {
            size 0.01 0.01 0.02
          }
        }
      ]
      name "ds"
      lookupTable [
        0 0 0
        0.1 0.1 0
        0.2 0.2 0
        0.3 0.3 0
        0.375 0.375 0
      ]
      type "laser"
      aperture 0.025
      gaussianWidth 0.5
    }
    Receiver {
      translation 0 0 0.075
      children [
        Shape {
          appearance PBRAppearance {
            baseColor 0 1 1
            roughness 1
            metalness 0
          }
          geometry Sphere {
            radius 0.005
          }
        }
      ]
      name "receiver(0)"
      type "infra-red"
      aperture 0.7461548752580024
    }
    Receiver {
      translation 0.0375 0 0.0649519
      rotation 0 1 0 0.523599
      children [
        Shape {
          appearance PBRAppearance {
            baseColor 0 1 1
            roughness 1
            metalness 0
          }
          geometry Sphere {
            radius 0.005
          }
        }
      ]
      name "receiver(1)"
      type "infra-red"
      aperture 0.7461548752580024
    }
    Receiver {
      translation 0.0649519 0 0.0375
      rotation 0 1 0 1.0472
      children [
        Shape {
          appearance PBRAppearance {
            baseColor 0 1 1
            roughness 1
            metalness 0
          }
          geometry Sphere {
            radius 0.005
          }
        }
      ]
      name "receiver(2)"
      type "infra-red"
      aperture 0.7461548752580024
    }
    Receiver {
      translation 0.075 0 0
      rotation 0 1 0 1.5708
      children [
        Shape {
          appearance PBRAppearance {
            baseColor 0 1 1
            roughness 1
            metalness 0
          }
          geometry Sphere {
            radius 0.005
          }
        }
      ]
      name "receiver(3)"
      type "infra-red"
      aperture 0.7461548752580024
    }
    Receiver {
      translation 0.0649519 0 -0.0375
      rotation 0 1 0 2.0944
      children [
        Shape {
          appearance PBRAppearance {
            baseColor 0 1 1
            roughness 1
            metalness 0
          }
          geometry Sphere {
            radius 0.005
          }
        }
      ]
      name "receiver(4)"
      type "infra-red"
      aperture 0.7461548752580024
    }
    Receiver {
      translation 0.0375 0 -0.0649519
      rotation 0 1 0 2.61799
      children [
        Shape {
          appearance PBRAppearance {
            baseColor 0 1 1
            roughness 1
            metalness 0
          }
          geometry Sphere {
            radius 0.005
          }
        }
      ]
      name "receiver(5)"
      type "infra-red"
      aperture 0.7461548752580024
    }
    Receiver {
      translation 0 0 -0.075
      rotation 0 1 0 3.14159
      children [
        Shape {
          appearance PBRAppearance {
            baseColor 0 1 1
            roughness 1
            metalness 0
          }
          geometry Sphere {
            radius 0.005
          }
        }
      ]
      name "receiver(6)"
      type "infra-red"
      aperture 0.7461548752580024
    }
    Receiver {
      translation -0.0375 0 -0.0649519
      rotation 0 1 0 -2.61799
      children [
        Shape {
          appearance PBRAppearance {
            baseColor 0 1 1
            roughness 1
            metalness 0
          }
          geometry Sphere {
            radius 0.005
          }
        }
      ]
      name "receiver(7)"
      type "infra-red"
      aperture 0.7461548752580024
    }
    Receiver {
      translation -0.0649519 0 -0.0375
      rotation 0 1 0 -2.0944
      children [
        Shape {
          appearance PBRAppearance {
            baseColor 0 1 1
            roughness 1
            metalness 0
          }
          geometry Sphere {
            radius 0.005
          }
        }
      ]
      name "receiver(8)"
      type "infra-red"
      aperture 0.7461548752580024
    }
    Receiver {
      translation -0.075 0 0
      rotation 0 1 0 -1.5708
      children [
        Shape {
          appearance PBRAppearance {
            baseColor 0 1 1
            roughness 1
            metalness 0
          }
          geometry Sphere {
            radius 0.005
          }
        }
      ]
      name "receiver(9)"
      type "infra-red"
      aperture 0.7461548752580024
    }
    Receiver {
      translation -0.0649519 0 0.0375
      rotation 0 1 0 -1.0472
      children [
        Shape {
          appearance PBRAppearance {
            baseColor 0 1 1
            roughness 1
            metalness 0
          }
          geometry Sphere {
            radius 0.005
          }
        }
      ]
      name "receiver(10)"
      type "infra-red"
      aperture 0.7461548752580024
    }
    Receiver {
      translation -0.0375 0 0.0649519
      rotation 0 1 0 -0.523599
      children [
        Shape {
          appearance PBRAppearance {
            baseColor 0 1 1
            roughness 1
            metalness 0
          }
          geometry Sphere {
            radius 0.005
          }
        }
      ]
      name "receiver(11)"
      type "infra-red"
      aperture 0.7461548752580024
    }
    Emitter {
      translation 0 0.0055 0.075
      children [
        Shape {
          appearance PBRAppearance {
            baseColor 1 1 0
            roughness 1
            metalness 0
          }
          geometry Sphere {
            radius 0.005
          }
        }
      ]
      name "emitter(0)"
      type "infra-red"
      range 0.3
      maxRange 0.3
      aperture 0.170196222099557
    }
    Emitter {
      translation 0.0375 0.0055 0.0649519
      rotation 0 1 0 0.523599
      children [
        Shape {
          appearance PBRAppearance {
            baseColor 1 1 0
            roughness 1
            metalness 0
          }
          geometry Sphere {
            radius 0.005
          }
        }
      ]
      name "emitter(1)"
      type "infra-red"
      range 0.3
      maxRange 0.3
      aperture 0.170196222099557
    }
    Emitter {
      translation 0.0649519 0.0055 0.0375
      rotation 0 1 0 1.0472
      children [
        Shape {
          appearance PBRAppearance {
            baseColor 1 1 0
            roughness 1
            metalness 0
          }
          geometry Sphere {
            radius 0.005
          }
        }
      ]
      name "emitter(2)"
      type "infra-red"
      range 0.3
      maxRange 0.3
      aperture 0.170196222099557
    }
    Emitter {
      translation 0.075 0.0055 0
      rotation 0 1 0 1.5708
      children [
        Shape {
          appearance PBRAppearance {
            baseColor 1 1 0
            roughness 1
            metalness 0
          }
          geometry Sphere {
            radius 0.005
          }
        }
      ]
      name "emitter(3)"
      type "infra-red"
      range 0.3
      maxRange 0.3
      aperture 0.170196222099557
    }
    Emitter {
      translation 0.0649519 0.0055 -0.0375
      rotation 0 1 0 2.0944
      children [
        Shape {
          appearance PBRAppearance {
            baseColor 1 1 0
            roughness 1
            metalness 0
          }
          geometry Sphere {
            radius 0.005
          }
        }
      ]
      name "emitter(4)"
      type "infra-red"
      range 0.3
      maxRange 0.3
      aperture 0.170196222099557
    }
    Emitter {
      translation 0.0375 0.0055 -0.0649519
      rotation 0 1 0 2.61799
      children [
        Shape {
          appearance PBRAppearance {
            baseColor 1 1 0
            roughness 1
            metalness 0
          }
          geometry Sphere {
            radius 0.005
          }
        }
      ]
      name "emitter(5)"
      type "infra-red"
      range 0.3
      maxRange 0.3
      aperture 0.170196222099557
    }
    Emitter {
      translation 0 0.0055 -0.075
      rotation 0 1 0 3.14159
      children [
        Shape {
          appearance PBRAppearance {
            baseColor 1 1 0
            roughness 1
            metalness 0
          }
          geometry Sphere {
            radius 0.005
          }
        }
      ]
      name "emitter(6)"
      type "infra-red"
      range 0.3
      maxRange 0.3
      aperture 0.170196222099557
    }
    Emitter {
      translation -0.0375 0.0055 -0.0649519
      rotation 0 1 0 -2.61799
      children [
        Shape {
          appearance PBRAppearance {
            baseColor 1 1 0
            roughness 1
            metalness 0
          }
          geometry Sphere {
            radius 0.005
          }
        }
      ]
      name "emitter(7)"
      type "infra-red"
      range 0.3
      maxRange 0.3
      aperture 0.170196222099557
    }
    Emitter {
      translation -0.0649519 0.0055 -0.0375
      rotation 0 1 0 -2.0944
      children [
        Shape {
          appearance PBRAppearance {
            baseColor 1 1 0
            roughness 1
            metalness 0
          }
          geometry Sphere {
            radius 0.005
          }
        }
      ]
      name "emitter(8)"
      type "infra-red"
      range 0.3
      maxRange 0.3
      aperture 0.170196222099557
    }
    Emitter {
      translation -0.075 0.0055 0
      rotation 0 1 0 -1.5708
      children [
        Shape {
          appearance PBRAppearance {
            baseColor 1 1 0
            roughness 1
            metalness 0
          }
          geometry Sphere {
            radius 0.005
          }
        }
      ]
      name "emitter(9)"
      type "infra-red"
      range 0.3
      maxRange 0.3
      aperture 0.170196222099557
    }
    Emitter {
      translation -0.0649519 0.0055 0.0375
      rotation 0 1 0 -1.0472
      children [
        Shape {
          appearance PBRAppearance {
            baseColor 1 1 0
            roughness 1
            metalness 0
          }
          geometry Sphere {
            radius 0.005
          }
        }
      ]
      name "emitter(10)"
      type "infra-red"
      range 0.3
      maxRange 0.3
      aperture 0.170196222099557
    }
    Emitter {
      translation -0.0375 0.0055 0.0649519
      rotation 0 1 0 -0.523599
      children [
        Shape {
          appearance PBRAppearance {
            baseColor 1 1 0
            roughness 1
            metalness 0
          }
          geometry Sphere {
            radius 0.005
          }
        }
      ]
      name "emitter(11)"
      type "infra-red"
      range 0.3
      maxRange 0.3
      aperture 0.170196222099557
    }
    Compass {
      rotation 0 1 0 -1.5708
      name "cp"
      lookupTable [
        -1 -1 0
        -0.707106 -0.707106 0
        0 0 0
        0.707106 0.707106 0
        1 1 0
      ]
      yAxis FALSE
    }
    HingeJoint {
      jointParameters HingeJointParameters {
        position 154.13484691268647
        anchor 0.045 0 0
      }
      device [
        PositionSensor {
          name "ps1"
        }
        RotationalMotor {
          name "wheel1"
          acceleration 0.4986655005698084
        }
      ]
      endPoint Solid {
        translation 0.044999906725811556 -1.6580930141785706e-06 1.692998311292778e-06
        rotation 0.9999999999999999 4.505397002046934e-12 -3.587633551971501e-12 3.3342994331569145
        children [
          DEF TRANS_WHEEL1 Transform {
            rotation 0 0 1 1.5708
            children [
              Shape {
                appearance PBRAppearance {
                  baseColor 0 1 0
                  roughness 1
                  metalness 0
                }
                geometry Cylinder {
                  height 0.0125
                  radius 0.0525
                }
              }
            ]
          }
        ]
        name "solid(1)"
        boundingObject USE TRANS_WHEEL1
        physics Physics {
          density -1
          mass 0.5
        }
        linearVelocity 2.823853273912368e-09 -7.124256551971187e-07 2.821857770770972e-09
        angularVelocity 5.375001035897245e-08 -1.9002485905989605e-11 -5.378071693074654e-08
      }
    }
    HingeJoint {
      jointParameters HingeJointParameters {
        position -32.68665183029091
        anchor -0.045 0 0
      }
      device [
        PositionSensor {
          name "ps2"
        }
        RotationalMotor {
          name "wheel2"
          acceleration 0.4986655005698084
        }
      ]
      endPoint Solid {
        translation -0.04499989999478693 -2.5216667929240856e-06 -4.695725653375799e-07
        rotation -1 -2.8269522578149357e-12 2.654822484336349e-12 1.2666251871671095
        children [
          DEF TRANS_WHEEL2 Transform {
            rotation 0 0 1 1.5708
            children [
              Shape {
                appearance PBRAppearance {
                  baseColor 0 1 0
                  roughness 1
                  metalness 0
                }
                geometry Cylinder {
                  height 0.0125
                  radius 0.0525
                }
              }
            ]
          }
        ]
        name "solid(2)"
        boundingObject USE TRANS_WHEEL2
        physics Physics {
          density -1
          mass 0.5
        }
        linearVelocity 2.8225063381628925e-09 -7.104635853610771e-07 2.8205335815585487e-09
        angularVelocity 5.3719192767390106e-08 -1.900301386341151e-11 -5.3764132498263624e-08
      }
    }
    DEF BODY Group {
      children [
        Transform {
          translation 0 0.04 0.045
          rotation 1 0 0 1.5708
          children [
            Shape {
              appearance PBRAppearance {
                baseColor 1 0 0
                roughness 1
                metalness 0
              }
              geometry Capsule {
                height 0.02
                radius 0.005
              }
            }
          ]
        }
        Transform {
          translation 0 -0.04 0.045
          children [
            Shape {
              appearance PBRAppearance {
                baseColor 0 1 0
                roughness 1
                metalness 0
              }
              geometry Sphere {
                radius 0.0125
              }
            }
          ]
        }
        Transform {
          translation 0 -0.04 -0.045
          children [
            Shape {
              appearance PBRAppearance {
                baseColor 0 1 0
                roughness 1
                metalness 0
              }
              geometry Sphere {
                radius 0.0125
              }
            }
          ]
        }
        Shape {
          appearance PBRAppearance {
            baseColor 1 0.5 0
            roughness 1
            metalness 0
          }
          geometry Cylinder {
            height 0.08
            radius 0.075
          }
        }
      ]
    }
  ]
  name "robot(3)"
  contactMaterial "R"
  boundingObject USE BODY
  physics Physics {
    density -1
    mass 1
  }
  controller "newTest3"
  linearVelocity 2.800983271946409e-09 -7.16648146949283e-07 2.7989642693864415e-09
  angularVelocity 5.373889898306898e-08 -1.900433215940176e-11 -5.377470647328899e-08
}
Robot {
  translation 2.1245048588284057 0.0520585506314111 -2.1220705163040336
  rotation -1.5597681074166594e-05 0.9999999998601078 -6.041261167552392e-06 -1.57000000005669
  children [
    Accelerometer {
      rotation 0 1 0 -1.5708
      name "ac"
      lookupTable [
        -1 -9.80665 0
        0 0 0
        1 9.80665 0
      ]
      yAxis FALSE
      zAxis FALSE
    }
    DEF Main Receiver {
      name "rx"
      channel 1
    }
    DEF Main Emitter {
      name "tx"
      channel 1
    }
    DistanceSensor {
      translation 0 -0.02 0.075
      rotation 0 1 0 -1.5708
      children [
        Shape {
          appearance PBRAppearance {
            baseColor 1 0.5 0
            roughness 1
            metalness 0
          }
          geometry Box {
            size 0.01 0.01 0.02
          }
        }
      ]
      name "ds"
      lookupTable [
        0 0 0
        0.1 0.1 0
        0.2 0.2 0
        0.3 0.3 0
        0.375 0.375 0
      ]
      type "laser"
      aperture 0.025
      gaussianWidth 0.5
    }
    Receiver {
      translation 0 0 0.075
      children [
        Shape {
          appearance PBRAppearance {
            baseColor 0 1 1
            roughness 1
            metalness 0
          }
          geometry Sphere {
            radius 0.005
          }
        }
      ]
      name "receiver(0)"
      type "infra-red"
      aperture 0.7461548752580024
    }
    Receiver {
      translation 0.0375 0 0.0649519
      rotation 0 1 0 0.523599
      children [
        Shape {
          appearance PBRAppearance {
            baseColor 0 1 1
            roughness 1
            metalness 0
          }
          geometry Sphere {
            radius 0.005
          }
        }
      ]
      name "receiver(1)"
      type "infra-red"
      aperture 0.7461548752580024
    }
    Receiver {
      translation 0.0649519 0 0.0375
      rotation 0 1 0 1.0472
      children [
        Shape {
          appearance PBRAppearance {
            baseColor 0 1 1
            roughness 1
            metalness 0
          }
          geometry Sphere {
            radius 0.005
          }
        }
      ]
      name "receiver(2)"
      type "infra-red"
      aperture 0.7461548752580024
    }
    Receiver {
      translation 0.075 0 0
      rotation 0 1 0 1.5708
      children [
        Shape {
          appearance PBRAppearance {
            baseColor 0 1 1
            roughness 1
            metalness 0
          }
          geometry Sphere {
            radius 0.005
          }
        }
      ]
      name "receiver(3)"
      type "infra-red"
      aperture 0.7461548752580024
    }
    Receiver {
      translation 0.0649519 0 -0.0375
      rotation 0 1 0 2.0944
      children [
        Shape {
          appearance PBRAppearance {
            baseColor 0 1 1
            roughness 1
            metalness 0
          }
          geometry Sphere {
            radius 0.005
          }
        }
      ]
      name "receiver(4)"
      type "infra-red"
      aperture 0.7461548752580024
    }
    Receiver {
      translation 0.0375 0 -0.0649519
      rotation 0 1 0 2.61799
      children [
        Shape {
          appearance PBRAppearance {
            baseColor 0 1 1
            roughness 1
            metalness 0
          }
          geometry Sphere {
            radius 0.005
          }
        }
      ]
      name "receiver(5)"
      type "infra-red"
      aperture 0.7461548752580024
    }
    Receiver {
      translation 0 0 -0.075
      rotation 0 1 0 3.14159
      children [
        Shape {
          appearance PBRAppearance {
            baseColor 0 1 1
            roughness 1
            metalness 0
          }
          geometry Sphere {
            radius 0.005
          }
        }
      ]
      name "receiver(6)"
      type "infra-red"
      aperture 0.7461548752580024
    }
    Receiver {
      translation -0.0375 0 -0.0649519
      rotation 0 1 0 -2.61799
      children [
        Shape {
          appearance PBRAppearance {
            baseColor 0 1 1
            roughness 1
            metalness 0
          }
          geometry Sphere {
            radius 0.005
          }
        }
      ]
      name "receiver(7)"
      type "infra-red"
      aperture 0.7461548752580024
    }
    Receiver {
      translation -0.0649519 0 -0.0375
      rotation 0 1 0 -2.0944
      children [
        Shape {
          appearance PBRAppearance {
            baseColor 0 1 1
            roughness 1
            metalness 0
          }
          geometry Sphere {
            radius 0.005
          }
        }
      ]
      name "receiver(8)"
      type "infra-red"
      aperture 0.7461548752580024
    }
    Receiver {
      translation -0.075 0 0
      rotation 0 1 0 -1.5708
      children [
        Shape {
          appearance PBRAppearance {
            baseColor 0 1 1
            roughness 1
            metalness 0
          }
          geometry Sphere {
            radius 0.005
          }
        }
      ]
      name "receiver(9)"
      type "infra-red"
      aperture 0.7461548752580024
    }
    Receiver {
      translation -0.0649519 0 0.0375
      rotation 0 1 0 -1.0472
      children [
        Shape {
          appearance PBRAppearance {
            baseColor 0 1 1
            roughness 1
            metalness 0
          }
          geometry Sphere {
            radius 0.005
          }
        }
      ]
      name "receiver(10)"
      type "infra-red"
      aperture 0.7461548752580024
    }
    Receiver {
      translation -0.0375 0 0.0649519
      rotation 0 1 0 -0.523599
      children [
        Shape {
          appearance PBRAppearance {
            baseColor 0 1 1
            roughness 1
            metalness 0
          }
          geometry Sphere {
            radius 0.005
          }
        }
      ]
      name "receiver(11)"
      type "infra-red"
      aperture 0.7461548752580024
    }
    Emitter {
      translation 0 0.0055 0.075
      children [
        Shape {
          appearance PBRAppearance {
            baseColor 1 1 0
            roughness 1
            metalness 0
          }
          geometry Sphere {
            radius 0.005
          }
        }
      ]
      name "emitter(0)"
      type "infra-red"
      range 0.3
      maxRange 0.3
      aperture 0.170196222099557
    }
    Emitter {
      translation 0.0375 0.0055 0.0649519
      rotation 0 1 0 0.523599
      children [
        Shape {
          appearance PBRAppearance {
            baseColor 1 1 0
            roughness 1
            metalness 0
          }
          geometry Sphere {
            radius 0.005
          }
        }
      ]
      name "emitter(1)"
      type "infra-red"
      range 0.3
      maxRange 0.3
      aperture 0.170196222099557
    }
    Emitter {
      translation 0.0649519 0.0055 0.0375
      rotation 0 1 0 1.0472
      children [
        Shape {
          appearance PBRAppearance {
            baseColor 1 1 0
            roughness 1
            metalness 0
          }
          geometry Sphere {
            radius 0.005
          }
        }
      ]
      name "emitter(2)"
      type "infra-red"
      range 0.3
      maxRange 0.3
      aperture 0.170196222099557
    }
    Emitter {
      translation 0.075 0.0055 0
      rotation 0 1 0 1.5708
      children [
        Shape {
          appearance PBRAppearance {
            baseColor 1 1 0
            roughness 1
            metalness 0
          }
          geometry Sphere {
            radius 0.005
          }
        }
      ]
      name "emitter(3)"
      type "infra-red"
      range 0.3
      maxRange 0.3
      aperture 0.170196222099557
    }
    Emitter {
      translation 0.0649519 0.0055 -0.0375
      rotation 0 1 0 2.0944
      children [
        Shape {
          appearance PBRAppearance {
            baseColor 1 1 0
            roughness 1
            metalness 0
          }
          geometry Sphere {
            radius 0.005
          }
        }
      ]
      name "emitter(4)"
      type "infra-red"
      range 0.3
      maxRange 0.3
      aperture 0.170196222099557
    }
    Emitter {
      translation 0.0375 0.0055 -0.0649519
      rotation 0 1 0 2.61799
      children [
        Shape {
          appearance PBRAppearance {
            baseColor 1 1 0
            roughness 1
            metalness 0
          }
          geometry Sphere {
            radius 0.005
          }
        }
      ]
      name "emitter(5)"
      type "infra-red"
      range 0.3
      maxRange 0.3
      aperture 0.170196222099557
    }
    Emitter {
      translation 0 0.0055 -0.075
      rotation 0 1 0 3.14159
      children [
        Shape {
          appearance PBRAppearance {
            baseColor 1 1 0
            roughness 1
            metalness 0
          }
          geometry Sphere {
            radius 0.005
          }
        }
      ]
      name "emitter(6)"
      type "infra-red"
      range 0.3
      maxRange 0.3
      aperture 0.170196222099557
    }
    Emitter {
      translation -0.0375 0.0055 -0.0649519
      rotation 0 1 0 -2.61799
      children [
        Shape {
          appearance PBRAppearance {
            baseColor 1 1 0
            roughness 1
            metalness 0
          }
          geometry Sphere {
            radius 0.005
          }
        }
      ]
      name "emitter(7)"
      type "infra-red"
      range 0.3
      maxRange 0.3
      aperture 0.170196222099557
    }
    Emitter {
      translation -0.0649519 0.0055 -0.0375
      rotation 0 1 0 -2.0944
      children [
        Shape {
          appearance PBRAppearance {
            baseColor 1 1 0
            roughness 1
            metalness 0
          }
          geometry Sphere {
            radius 0.005
          }
        }
      ]
      name "emitter(8)"
      type "infra-red"
      range 0.3
      maxRange 0.3
      aperture 0.170196222099557
    }
    Emitter {
      translation -0.075 0.0055 0
      rotation 0 1 0 -1.5708
      children [
        Shape {
          appearance PBRAppearance {
            baseColor 1 1 0
            roughness 1
            metalness 0
          }
          geometry Sphere {
            radius 0.005
          }
        }
      ]
      name "emitter(9)"
      type "infra-red"
      range 0.3
      maxRange 0.3
      aperture 0.170196222099557
    }
    Emitter {
      translation -0.0649519 0.0055 0.0375
      rotation 0 1 0 -1.0472
      children [
        Shape {
          appearance PBRAppearance {
            baseColor 1 1 0
            roughness 1
            metalness 0
          }
          geometry Sphere {
            radius 0.005
          }
        }
      ]
      name "emitter(10)"
      type "infra-red"
      range 0.3
      maxRange 0.3
      aperture 0.170196222099557
    }
    Emitter {
      translation -0.0375 0.0055 0.0649519
      rotation 0 1 0 -0.523599
      children [
        Shape {
          appearance PBRAppearance {
            baseColor 1 1 0
            roughness 1
            metalness 0
          }
          geometry Sphere {
            radius 0.005
          }
        }
      ]
      name "emitter(11)"
      type "infra-red"
      range 0.3
      maxRange 0.3
      aperture 0.170196222099557
    }
    Compass {
      rotation 0 1 0 -1.5708
      name "cp"
      lookupTable [
        -1 -1 0
        -0.707106 -0.707106 0
        0 0 0
        0.707106 0.707106 0
        1 1 0
      ]
      yAxis FALSE
    }
    HingeJoint {
      jointParameters HingeJointParameters {
        position 154.13484691268636
        anchor 0.045 0 0
      }
      device [
        PositionSensor {
          name "ps1"
        }
        RotationalMotor {
          name "wheel1"
          acceleration 0.4986655005698084
        }
      ]
      endPoint Solid {
        translation 0.044999906725811556 -1.658093014178378e-06 1.6929983112929663e-06
        rotation 1 4.505397002046705e-12 -3.587633551971738e-12 3.3342994331568008
        children [
          DEF TRANS_WHEEL1 Transform {
            rotation 0 0 1 1.5708
            children [
              Shape {
                appearance PBRAppearance {
                  baseColor 0 1 0
                  roughness 1
                  metalness 0
                }
                geometry Cylinder {
                  height 0.0125
                  radius 0.0525
                }
              }
            ]
          }
        ]
        name "solid(1)"
        boundingObject USE TRANS_WHEEL1
        physics Physics {
          density -1
          mass 0.5
        }
        linearVelocity -2.0565904579464176e-09 -7.211577227341646e-07 2.884845658568613e-09
        angularVelocity 5.491413517405897e-08 -2.0174311699510404e-11 3.917174123514798e-08
      }
    }
    HingeJoint {
      jointParameters HingeJointParameters {
        position -32.68665183029679
        anchor -0.045 0 0
      }
      device [
        PositionSensor {
          name "ps2"
        }
        RotationalMotor {
          name "wheel2"
          acceleration 0.4986655005698084
        }
      ]
      endPoint Solid {
        translation -0.04499989999478693 -2.5216667929268452e-06 -4.695725653227628e-07
        rotation -1 -2.826952257795822e-12 2.6548224843340304e-12 1.2666251871729861
        children [
          DEF TRANS_WHEEL2 Transform {
            rotation 0 0 1 1.5708
            children [
              Shape {
                appearance PBRAppearance {
                  baseColor 0 1 0
                  roughness 1
                  metalness 0
                }
                geometry Cylinder {
                  height 0.0125
                  radius 0.0525
                }
              }
            ]
          }
        ]
        name "solid(2)"
        boundingObject USE TRANS_WHEEL2
        physics Physics {
          density -1
          mass 0.5
        }
        linearVelocity -2.054684679111994e-09 -7.16224294267899e-07 2.881403001508384e-09
        angularVelocity 5.4914288439097225e-08 -2.017308125823097e-11 3.913469672148055e-08
      }
    }
    DEF BODY Group {
      children [
        Transform {
          translation 0 0.04 0.045
          rotation 1 0 0 1.5708
          children [
            Shape {
              appearance PBRAppearance {
                baseColor 1 0 0
                roughness 1
                metalness 0
              }
              geometry Capsule {
                height 0.02
                radius 0.005
              }
            }
          ]
        }
        Transform {
          translation 0 -0.04 0.045
          children [
            Shape {
              appearance PBRAppearance {
                baseColor 0 1 0
                roughness 1
                metalness 0
              }
              geometry Sphere {
                radius 0.0125
              }
            }
          ]
        }
        Transform {
          translation 0 -0.04 -0.045
          children [
            Shape {
              appearance PBRAppearance {
                baseColor 0 1 0
                roughness 1
                metalness 0
              }
              geometry Sphere {
                radius 0.0125
              }
            }
          ]
        }
        Shape {
          appearance PBRAppearance {
            baseColor 1 0.5 0
            roughness 1
            metalness 0
          }
          geometry Cylinder {
            height 0.08
            radius 0.075
          }
        }
      ]
    }
  ]
  name "robot(1)"
  contactMaterial "R"
  boundingObject USE BODY
  physics Physics {
    density -1
    mass 1
  }
  controller "newTest1"
  linearVelocity -2.039443345735147e-09 -7.238916070171979e-07 2.8605158402916263e-09
  angularVelocity 5.4914126049148404e-08 -2.0175740283543602e-11 3.91568568357867e-08
}
